Workbook
Name CARBON: Lists!$B$5:$B$6
Name carbonFactorNonGridElecNonRenew: 'Base year fuel types'!#REF!
Name carbonFactorOtherFuel01: 'Base year fuel types'!$D$18
Name carbonFactorOtherFuel02: 'Base year fuel types'!$D$19
Name carbonFactorOtherFuel03: 'Base year fuel types'!$D$20
Name carbonFactorOtherFuel04: 'Base year fuel types'!$D$21
Name carbonFactorOtherFuel05: 'Base year fuel types'!$D$22
Name carbonFactorOtherFuel06: 'Base year fuel types'!$D$23
Name carbonFactorOtherFuel07: 'Base year fuel types'!$D$24
Name carbonFactorOtherFuel08: 'Base year fuel types'!$D$25
Name carbonFactorOtherFuel09: 'Base year fuel types'!$D$26
Name carbonFactorOtherFuel10: 'Base year fuel types'!$D$27
Name carbonFactorOtherFuel11: 'Base year fuel types'!$D$28
Name ENERGY: Lists!$B$2:$B$4
Name facilityAddress: 'Facility details'!$B$5
Name facilityBaseYear: 'Facility targets'!$B$19
Name facilityBYStartDate: 'Facility details'!$B$6
Name facilityBYWeightedCarbonFactor: 'Base year fuel types'!$D$31
Name facilityID: 'Facility details'!$B$3
Name facilityInETS: 'Facility details'!$B$9
Name facilityName: 'Facility details'!$B$4
Name facilityTargetTP7: 'Facility targets'!$C$13
Name facilityTargetTP8: 'Facility targets'!$C$15
Name facilityTargetTP9: 'Facility targets'!$C$17
Name fixedPrimaryAmount: 'Base year data split'!$G$4
Name fixedThroughput: 'Base year data split'!$D$4
Name fixedThroughputUnit: 'Base year data split'!$E$4
Name fixWkly: 'Weekly BY multi-prod'!$B$59
Name nameOtherFuel01: 'Base year fuel types'!$A$18
Name nameOtherFuel02: 'Base year fuel types'!$A$19
Name nameOtherFuel03: 'Base year fuel types'!$A$20
Name nameOtherFuel04: 'Base year fuel types'!$A$21
Name nameOtherFuel05: 'Base year fuel types'!$A$22
Name nameOtherFuel06: 'Base year fuel types'!$A$23
Name nameOtherFuel07: 'Base year fuel types'!$A$24
Name nameOtherFuel08: 'Base year fuel types'!$A$25
Name nameOtherFuel09: 'Base year fuel types'!$A$26
Name nameOtherFuel10: 'Base year fuel types'!$A$27
Name nameOtherFuel11: 'Base year fuel types'!$A$28
Name primaryAmountAll: 'Base year fuel types'!$E$29
Name primaryBaseYearEnergy: 'Base year fuel types'!$E$29
Name primaryBaseYearEnergy: 'Base year fuel types'!$E$29
Name primaryBaseYearEnergy: 'Base year fuel types'!$E$29
Name primaryBaseYearEnergy: 'Base year fuel types'!$E$29
Name primaryCoal: 'Base year fuel types'!$E$8
Name primaryCoke: 'Base year fuel types'!$E$9
Name primaryConversionFactor: 'Base year fuel types'!#REF!
Name primaryEthane: 'Base year fuel types'!$E$11
Name primaryFuelOil: 'Base year fuel types'!$E$7
Name primaryGasOil: 'Base year fuel types'!$E$14
Name primaryGridElec: 'Base year fuel types'!$E$4
Name primaryKerosene: 'Base year fuel types'!$E$12
Name primaryLPG: 'Base year fuel types'!$E$10
Name primaryNaphtha: 'Base year fuel types'!$E$15
Name primaryNaturalGas: 'Base year fuel types'!$E$6
Name primaryNonGridElecNonRenew: 'Base year fuel types'!#REF!
Name primaryNonGridElecRenewables: 'Base year fuel types'!$E$5
Name primaryOtherFuel01: 'Base year fuel types'!$E$18
Name primaryOtherFuel02: 'Base year fuel types'!$E$19
Name primaryOtherFuel03: 'Base year fuel types'!$E$20

Sheet Facility details
A1: Complete the fields below about the facility you are applying to add to a Climate Change Agreement
A3: Facility identifier
A4: Facility name
A5: Facility address
A6: Base year start date | C6: =IF(B6="","",IF(1-YEARFRAC(B6,DATE(YEAR(B6),12,31)+1,1)<=0.5,YEAR(B6),YEAR(B6)+1))
A7: Will this facility be joining an agreement with an ENERGY or CARBON based improvement target?
A8: Select the reporting units for the agreement
A9: Are any activities at this facility consuming fuels whose emissions are reported in the UK Emissions Trading Scheme?
A10: =IF(B9="Yes","Note: you must exclude the energy consumed by activities whose emissions are reported under the UK ETS scheme","")
A11: Progress: | B11: =COUNTA(B3:B9)/7 -> 0

Sheet Base year fuel types
A1: ="Complete the details in the table for each energy type consumed during the 12 month base year period "&IF('Facility details'!B6<>"","(beginning "&TEXT('Facility details'!B6,"dd/mm/yyyy")&")","") -> Complete the details in the table for each energy type consumed during the 12 month base year period
A3: Energy type | B3: ="DELIVERED base year ENERGY (excluding ETS) "&IF(targetType="ENERGY",reportingUnits,"kWh") -> DELIVERED base year ENERGY (excluding ETS) kWh | C3: Primary energy conversion factor | D3: ="Primary carbon emission factor kgCe/"&IF(targetType="ENERGY",reportingUnits,"kWh") -> Primary carbon emission factor kgCe/kWh | E3: ="PRIMARY base year "&targetType&" (excluding ETS) "&reportingUnits -> PRIMARY base year (excluding ETS) | F3: Base year emissions tCO2e
A4: Grid electricity and electricity from combustion of a renewable fuel | C4: 2.1 | D4: {=0.21097*12/44/'Base year fuel types'!$C4 *_xlfn.IFS( reportingUnits="MWh",1000, reportingUnits="GJ",1000/3.6, OR(reportingUnits="kWh",reportingUnits="kgC",reportingUnits="tonneC",reportingUnits=""),1 )} -> 0.027398701 | E4: ='Base year fuel types'!$B4*'Base year fuel types'!$C4*IF(targetType="CARBON",D4,1) -> 0 | F4: ='Base year fuel types'!$E4*IF(targetType="CARBON",1,'Base year fuel types'!$D4)*44/12/1000 -> 0
A5: Non-grid electricity from renewable sources (PV, hydro and wind) | C5: 1 | D5: 0 | E5: ='Base year fuel types'!$B5*'Base year fuel types'!$C5*IF(targetType="CARBON",D5,1) -> 0 | F5: ='Base year fuel types'!$E5*IF(targetType="CARBON",1,'Base year fuel types'!$D5)*44/12/1000 -> 0
A6: Natural Gas | C6: 1 | D6: {=Fuels!F42*12/44 *_xlfn.IFS( reportingUnits="MWh",1000, reportingUnits="GJ",1000/3.6, OR(reportingUnits="kWh",reportingUnits="kgC",reportingUnits="tonneC",reportingUnits=""),1 )} -> 0.049688182 | E6: ='Base year fuel types'!$B6*'Base year fuel types'!$C6*IF(targetType="CARBON",D6,1) -> 0 | F6: ='Base year fuel types'!$E6*IF(targetType="CARBON",1,'Base year fuel types'!$D6)*44/12/1000 -> 0
A7: Fuel Oil | C7: 1 | D7: {=Fuels!F82*12/44 *_xlfn.IFS( reportingUnits="MWh",1000, reportingUnits="GJ",1000/3.6, OR(reportingUnits="kWh",reportingUnits="kgC",reportingUnits="tonneC",reportingUnits=""),1 )} -> 0.072842727 | E7: ='Base year fuel types'!$B7*'Base year fuel types'!$C7*IF(targetType="CARBON",D7,1) -> 0 | F7: ='Base year fuel types'!$E7*IF(targetType="CARBON",1,'Base year fuel types'!$D7)*44/12/1000 -> 0
A8: Coal (referred to as Coal (Industrial) in GHG Company Reporting) | C8: 1 | D8: {=Fuels!F133*12/44 *_xlfn.IFS( reportingUnits="MWh",1000, reportingUnits="GJ",1000/3.6, OR(reportingUnits="kWh",reportingUnits="kgC",reportingUnits="tonneC",reportingUnits=""),1 )} -> 0.087586364 | E8: ='Base year fuel types'!$B8*'Base year fuel types'!$C8*IF(targetType="CARBON",D8,1) -> 0 | F8: ='Base year fuel types'!$E8*IF(targetType="CARBON",1,'Base year fuel types'!$D8)*44/12/1000 -> 0
A9: Coke | C9: 1 | D9: {=0.117 *_xlfn.IFS( reportingUnits="MWh",1000, reportingUnits="GJ",1000/3.6, OR(reportingUnits="kWh",reportingUnits="kgC",reportingUnits="tonneC",reportingUnits=""),1 )} -> 0.117 | E9: ='Base year fuel types'!$B9*'Base year fuel types'!$C9*IF(targetType="CARBON",D9,1) -> 0 | F9: ='Base year fuel types'!$E9*IF(targetType="CARBON",1,'Base year fuel types'!$D9)*44/12/1000 -> 0
A10: LPG | C10: 1 | D10: {=Fuels!F38*12/44 *_xlfn.IFS( reportingUnits="MWh",1000, reportingUnits="GJ",1000/3.6, OR(reportingUnits="kWh",reportingUnits="kgC",reportingUnits="tonneC",reportingUnits=""),1 )} -> 0.058415455 | E10: ='Base year fuel types'!$B10*'Base year fuel types'!$C10*IF(targetType="CARBON",D10,1) -> 0 | F10: ='Base year fuel types'!$E10*IF(targetType="CARBON",1,'Base year fuel types'!$D10)*44/12/1000 -> 0
A11: Ethane | C11: 1 | D11: {=0.0545 *_xlfn.IFS( reportingUnits="MWh",1000, reportingUnits="GJ",1000/3.6, OR(reportingUnits="kWh",reportingUnits="kgC",reportingUnits="tonneC",reportingUnits=""),1 )} -> 0.0545 | E11: ='Base year fuel types'!$B11*'Base year fuel types'!$C11*IF(targetType="CARBON",D11,1) -> 0 | F11: ='Base year fuel types'!$E11*IF(targetType="CARBON",1,'Base year fuel types'!$D11)*44/12/1000 -> 0
A12: Kerosene (referred to as Burning Oil in GHG Company Reporting) | C12: 1 | D12: {=Fuels!F70*12/44 *_xlfn.IFS( reportingUnits="MWh",1000, reportingUnits="GJ",1000/3.6, OR(reportingUnits="kWh",reportingUnits="kgC",reportingUnits="tonneC",reportingUnits=""),1 )} -> 0.066973636 | E12: ='Base year fuel types'!$B12*'Base year fuel types'!$C12*IF(targetType="CARBON",D12,1) -> 0 | F12: ='Base year fuel types'!$E12*IF(targetType="CARBON",1,'Base year fuel types'!$D12)*44/12/1000 -> 0
A13: Petrol (referred to as Petrol (average biofuel blend) in GHG Company Reporting) | C13: 1 | D13: {=Fuels!F98*12/44 *_xlfn.IFS( reportingUnits="MWh",1000, reportingUnits="GJ",1000/3.6, OR(reportingUnits="kWh",reportingUnits="kgC",reportingUnits="tonneC",reportingUnits=""),1 )} -> 0.061568182 | E13: ='Base year fuel types'!$B13*'Base year fuel types'!$C13*IF(targetType="CARBON",D13,1) -> 0 | F13: ='Base year fuel types'!$E13*IF(targetType="CARBON",1,'Base year fuel types'!$D13)*44/12/1000 -> 0
A14: Gasoil/Diesel (referred to as Gas Oil in GHG Company Reporting) | C14: 1 | D14: {=Fuels!F86*12/44 *_xlfn.IFS( reportingUnits="MWh",1000, reportingUnits="GJ",1000/3.6, OR(reportingUnits="kWh",reportingUnits="kgC",reportingUnits="tonneC",reportingUnits=""),1 )} -> 0.069160909 | E14: ='Base year fuel types'!$B14*'Base year fuel types'!$C14*IF(targetType="CARBON",D14,1) -> 0 | F14: ='Base year fuel types'!$E14*IF(targetType="CARBON",1,'Base year fuel types'!$D14)*44/12/1000 -> 0
A15: Naphtha | C15: 1 | D15: {=Fuels!F94*12/44 *_xlfn.IFS( reportingUnits="MWh",1000, reportingUnits="GJ",1000/3.6, OR(reportingUnits="kWh",reportingUnits="kgC",reportingUnits="tonneC",reportingUnits=""),1 )} -> 0.064265455 | E15: ='Base year fuel types'!$B15*'Base year fuel types'!$C15*IF(targetType="CARBON",D15,1) -> 0 | F15: ='Base year fuel types'!$E15*IF(targetType="CARBON",1,'Base year fuel types'!$D15)*44/12/1000 -> 0
A16: Petroleum coke | C16: 1 | D16: {=Fuels!F145*12/44 *_xlfn.IFS( reportingUnits="MWh",1000, reportingUnits="GJ",1000/3.6, OR(reportingUnits="kWh",reportingUnits="kgC",reportingUnits="tonneC",reportingUnits=""),1 )} -> 0.092719091 | E16: ='Base year fuel types'!$B16*'Base year fuel types'!$C16*IF(targetType="CARBON",D16,1) -> 0 | F16: ='Base year fuel types'!$E16*IF(targetType="CARBON",1,'Base year fuel types'!$D16)*44/12/1000 -> 0
A17: Refinery Gas (referred to as Other Petroleum Gas in GHG Company Reporting) | C17: 1 | D17: {=Fuels!F50*12/44 *_xlfn.IFS( reportingUnits="MWh",1000, reportingUnits="GJ",1000/3.6, OR(reportingUnits="kWh",reportingUnits="kgC",reportingUnits="tonneC",reportingUnits=""),1 )} -> 0.049922727 | E17: ='Base year fuel types'!$B17*'Base year fuel types'!$C17*IF(targetType="CARBON",D17,1) -> 0 | F17: ='Base year fuel types'!$E17*IF(targetType="CARBON",1,'Base year fuel types'!$D17)*44/12/1000 -> 0
A18: Other Fuel 01 | C18: 1 | E18: ='Base year fuel types'!$B18*'Base year fuel types'!$C18*IF(targetType="CARBON",D18,1) -> 0 | F18: ='Base year fuel types'!$E18*IF(targetType="CARBON",1,'Base year fuel types'!$D18)*44/12/1000 -> 0
A19: Other Fuel 02 | C19: 1 | E19: ='Base year fuel types'!$B19*'Base year fuel types'!$C19*IF(targetType="CARBON",D19,1) -> 0 | F19: ='Base year fuel types'!$E19*IF(targetType="CARBON",1,'Base year fuel types'!$D19)*44/12/1000 -> 0
A20: Other Fuel 03 | C20: 1 | E20: ='Base year fuel types'!$B20*'Base year fuel types'!$C20*IF(targetType="CARBON",D20,1) -> 0 | F20: ='Base year fuel types'!$E20*IF(targetType="CARBON",1,'Base year fuel types'!$D20)*44/12/1000 -> 0
A21: Other Fuel 04 | C21: 1 | E21: ='Base year fuel types'!$B21*'Base year fuel types'!$C21*IF(targetType="CARBON",D21,1) -> 0 | F21: ='Base year fuel types'!$E21*IF(targetType="CARBON",1,'Base year fuel types'!$D21)*44/12/1000 -> 0
A22: Other Fuel 05 | C22: 1 | E22: ='Base year fuel types'!$B22*'Base year fuel types'!$C22*IF(targetType="CARBON",D22,1) -> 0 | F22: ='Base year fuel types'!$E22*IF(targetType="CARBON",1,'Base year fuel types'!$D22)*44/12/1000 -> 0
A23: Other Fuel 06 | C23: 1 | E23: ='Base year fuel types'!$B23*'Base year fuel types'!$C23*IF(targetType="CARBON",D23,1) -> 0 | F23: ='Base year fuel types'!$E23*IF(targetType="CARBON",1,'Base year fuel types'!$D23)*44/12/1000 -> 0
A24: Other Fuel 07 | C24: 1 | E24: ='Base year fuel types'!$B24*'Base year fuel types'!$C24*IF(targetType="CARBON",D24,1) -> 0 | F24: ='Base year fuel types'!$E24*IF(targetType="CARBON",1,'Base year fuel types'!$D24)*44/12/1000 -> 0
A25: Other Fuel 08 | C25: 1 | E25: ='Base year fuel types'!$B25*'Base year fuel types'!$C25*IF(targetType="CARBON",D25,1) -> 0 | F25: ='Base year fuel types'!$E25*IF(targetType="CARBON",1,'Base year fuel types'!$D25)*44/12/1000 -> 0
A26: Other Fuel 09 | C26: 1 | E26: ='Base year fuel types'!$B26*'Base year fuel types'!$C26*IF(targetType="CARBON",D26,1) -> 0 | F26: ='Base year fuel types'!$E26*IF(targetType="CARBON",1,'Base year fuel types'!$D26)*44/12/1000 -> 0
A27: Other Fuel 10 | C27: 1 | E27: ='Base year fuel types'!$B27*'Base year fuel types'!$C27*IF(targetType="CARBON",D27,1) -> 0 | F27: ='Base year fuel types'!$E27*IF(targetType="CARBON",1,'Base year fuel types'!$D27)*44/12/1000 -> 0
A28: Other Fuel 11 | C28: 1 | E28: ='Base year fuel types'!$B28*'Base year fuel types'!$C28*IF(targetType="CARBON",D28,1) -> 0 | F28: ='Base year fuel types'!$E28*IF(targetType="CARBON",1,'Base year fuel types'!$D28)*44/12/1000 -> 0
A29: Totals: | B29: =SUBTOTAL(109,'Base year fuel types'!$B$4:$B$28) -> 0 | E29: =SUBTOTAL(109,'Base year fuel types'!$E$4:$E$28) -> 0 | F29: =SUBTOTAL(109,'Base year fuel types'!$F$4:$F$28) -> 0
A31: Weighted average base year carbon emission factor: | D31: =IFERROR(SUMPRODUCT('Base year fuel types'!E4:E28,'Base year fuel types'!D4:D28)/SUM('Base year fuel types'!E4:E28),"") | E31: ="kgCe/"&IF(targetType="ENERGY",reportingUnits,"kWh") -> kgCe/kWh

Sheet Base year data split
A1: ="Complete the table below to attribute all primary "&targetType&" in the base year to the FIXED and/or VARIABLE components at this facility" -> Complete the table below to attribute all primary in the base year to the FIXED and/or VARIABLE components at this facility
A3: =targetType&" component" -> component | B3: Product group name | C3: Product group base year | D3: Base year throughput | E3: Throughput unit | F3: =targetType&" intensity "&reportingUnits&"/throughput unit" -> intensity /throughput unit | G3: ="Primary "&targetType&" during base year" -> Primary during base year
A4: ="Fixed "&targetType -> Fixed | H4: ← If you have attributed all the facility's energy to FIXED, you must enter the base year throughput and throughput units
A5: ="Variable "&targetType&" (Site total)" -> Variable (Site total) | G5: =IF(C5=facilityBaseYear,'Base year data split'!$D5*'Base year data split'!$F5,"") -> 0 | H5: ← Do not complete this row if you have entered data for one or more different product groups.
A6: ="Variable "&targetType&" ("& IF(variableProductName01<>"",variableProductName01,"Product group 1") &")" -> Variable (Product group 1) | G6: =IF(C6=facilityBaseYear,'Base year data split'!$D6*'Base year data split'!$F6,"") -> 0 | H6: ← Do not complete any Product Group rows if you have entered data for the Site Total row.
A7: ="Variable "&targetType&" ("& IF(variableProductName02<>"",variableProductName02,"Product group 2") &")" -> Variable (Product group 2) | G7: =IF(C7=facilityBaseYear,'Base year data split'!$D7*'Base year data split'!$F7,"") -> 0
A8: ="Variable "&targetType&" ("& IF(variableProductName03<>"",variableProductName03,"Product group 3") &")" -> Variable (Product group 3) | G8: =IF(C8=facilityBaseYear,'Base year data split'!$D8*'Base year data split'!$F8,"") -> 0
A9: ="Variable "&targetType&" ("& IF(variableProductName04<>"",variableProductName04,"Product group 4") &")" -> Variable (Product group 4) | G9: =IF(C9=facilityBaseYear,'Base year data split'!$D9*'Base year data split'!$F9,"") -> 0
A10: ="Variable "&targetType&" ("& IF(variableProductName05<>"",variableProductName05,"Product group 5") &")" -> Variable (Product group 5) | G10: =IF(C10=facilityBaseYear,'Base year data split'!$D10*'Base year data split'!$F10,"") -> 0
A11: ="Variable "&targetType&" ("& IF(variableProductName06<>"",variableProductName06,"Product group 6") &")" -> Variable (Product group 6) | G11: =IF(C11=facilityBaseYear,'Base year data split'!$D11*'Base year data split'!$F11,"") -> 0
A12: ="Variable "&targetType&" ("& IF(variableProductName07<>"",variableProductName07,"Product group 7") &")" -> Variable (Product group 7) | G12: =IF(C12=facilityBaseYear,'Base year data split'!$D12*'Base year data split'!$F12,"") -> 0
A13: ="Variable "&targetType&" ("& IF(variableProductName08<>"",variableProductName08,"Product group 8") &")" -> Variable (Product group 8) | G13: =IF(C13=facilityBaseYear,'Base year data split'!$D13*'Base year data split'!$F13,"") -> 0
A14: ="Variable "&targetType&" ("& IF(variableProductName09<>"",variableProductName09,"Product group 9") &")" -> Variable (Product group 9) | G14: =IF(C14=facilityBaseYear,'Base year data split'!$D14*'Base year data split'!$F14,"") -> 0
A15: ="Variable "&targetType&" ("& IF(variableProductName10<>"",variableProductName10,"Product group 10") &")" -> Variable (Product group 10) | G15: =IF(C15=facilityBaseYear,'Base year data split'!$D15*'Base year data split'!$F15,"") -> 0
A16: ="Variable "&targetType&" ("& IF(variableProductName11<>"",variableProductName11,"Product group 11") &")" -> Variable (Product group 11) | G16: =IF(C16=facilityBaseYear,'Base year data split'!$D16*'Base year data split'!$F16,"") -> 0
A17: ="Variable "&targetType&" ("& IF(variableProductName12<>"",variableProductName12,"Product group 12") &")" -> Variable (Product group 12) | G17: =IF(C17=facilityBaseYear,'Base year data split'!$D17*'Base year data split'!$F17,"") -> 0
A18: ="Variable "&targetType&" ("& IF(variableProductName13<>"",variableProductName13,"Product group 13") &")" -> Variable (Product group 13) | G18: =IF(C18=facilityBaseYear,'Base year data split'!$D18*'Base year data split'!$F18,"") -> 0
A19: ="Variable "&targetType&" ("& IF(variableProductName14<>"",variableProductName14,"Product group 14") &")" -> Variable (Product group 14) | G19: =IF(C19=facilityBaseYear,'Base year data split'!$D19*'Base year data split'!$F19,"") -> 0
A20: ="Variable "&targetType&" ("& IF(variableProductName15<>"",variableProductName15,"Product group 15") &")" -> Variable (Product group 15) | G20: =IF(C20=facilityBaseYear,'Base year data split'!$D20*'Base year data split'!$F20,"") -> 0
A21: Total | G21: =SUBTOTAL(109,'Base year data split'!$G$4:$G$20) -> 0
A23: ="Total primary base year "&targetType&" (excluding ETS) from the ""BY data by fuel type"" tab" -> Total primary base year (excluding ETS) from the "BY data by fuel type" tab | G23: =primaryAmountAll -> 0 | H23: =IF(reportingUnits="","",reportingUnits)
A25: ="Amount of "&targetType&" you need to attribute to FIXED and/or VARIABLE components in the table above" -> Amount of you need to attribute to FIXED and/or VARIABLE components in the table above | G25: =primaryAmountAll-G21 -> 0 | H25: =IF(reportingUnits="","",reportingUnits)
A27: Progress | G27: =IFERROR(G21/G23,0) -> 0

Sheet Facility targets
A1: Enter the sector commitment values for the sector (or sub-sector where applicable) for each target period in the table
A3: Target period | B3: Sector commitment
A4: TP7
A5: TP8
A6: TP9
A8: Year | B8: Sector commitment | C8: Facility target
A9: 2022 | B9: =sectorTargetTP7*(Table1[[#This Row],[Year]]-2022)/4 -> 0 | C9: =IF(facilityBaseYear>=Table1[[#This Row],[Year]],0,1-(1-Table1[[#This Row],[Sector commitment]])/(1-_xlfn.XLOOKUP(facilityBaseYear,Table1[Year],Table1[Sector commitment]))) -> 0
A10: 2023 | B10: =sectorTargetTP7*(Table1[[#This Row],[Year]]-2022)/4 -> 0 | C10: =IF(facilityBaseYear>=Table1[[#This Row],[Year]],0,1-(1-Table1[[#This Row],[Sector commitment]])/(1-_xlfn.XLOOKUP(facilityBaseYear,Table1[Year],Table1[Sector commitment]))) -> 0
A11: 2024 | B11: =sectorTargetTP7*(Table1[[#This Row],[Year]]-2022)/4 -> 0 | C11: =IF(facilityBaseYear>=Table1[[#This Row],[Year]],0,1-(1-Table1[[#This Row],[Sector commitment]])/(1-_xlfn.XLOOKUP(facilityBaseYear,Table1[Year],Table1[Sector commitment]))) -> 0
A12: 2025 | B12: =sectorTargetTP7*(Table1[[#This Row],[Year]]-2022)/4 -> 0 | C12: =IF(facilityBaseYear>=Table1[[#This Row],[Year]],0,1-(1-Table1[[#This Row],[Sector commitment]])/(1-_xlfn.XLOOKUP(facilityBaseYear,Table1[Year],Table1[Sector commitment]))) -> 0
A13: 2026 | B13: =sectorTargetTP7 -> 0 | C13: =IF(facilityBaseYear>=Table1[[#This Row],[Year]],0,1-(1-Table1[[#This Row],[Sector commitment]])/(1-_xlfn.XLOOKUP(facilityBaseYear,Table1[Year],Table1[Sector commitment]))) -> 0
A14: 2027 | B14: =sectorTargetTP7+(sectorTargetTP8-sectorTargetTP7)/2 -> 0 | C14: =IF(facilityBaseYear>=Table1[[#This Row],[Year]],0,1-(1-Table1[[#This Row],[Sector commitment]])/(1-_xlfn.XLOOKUP(facilityBaseYear,Table1[Year],Table1[Sector commitment]))) -> 0
A15: 2028 | B15: =sectorTargetTP8 -> 0 | C15: =IF(facilityBaseYear>=Table1[[#This Row],[Year]],0,1-(1-Table1[[#This Row],[Sector commitment]])/(1-_xlfn.XLOOKUP(facilityBaseYear,Table1[Year],Table1[Sector commitment]))) -> 0
A16: 2029 | B16: =sectorTargetTP8+(sectorTargetTP9-sectorTargetTP8)/2 -> 0 | C16: =IF(facilityBaseYear>=Table1[[#This Row],[Year]],0,1-(1-Table1[[#This Row],[Sector commitment]])/(1-_xlfn.XLOOKUP(facilityBaseYear,Table1[Year],Table1[Sector commitment]))) -> 0
A17: 2030 | B17: =sectorTargetTP9 -> 0 | C17: =IF(facilityBaseYear>=Table1[[#This Row],[Year]],0,1-(1-Table1[[#This Row],[Sector commitment]])/(1-_xlfn.XLOOKUP(facilityBaseYear,Table1[Year],Table1[Sector commitment]))) -> 0
A19: Base year | B19: =IF(facilityBYStartDate="","",IF(1-YEARFRAC(facilityBYStartDate,DATE(YEAR(facilityBYStartDate),12,31)+1,1)<=0.5,YEAR(facilityBYStartDate),YEAR(facilityBYStartDate)+1))

Sheet Data for MyCCA
A1: Tab name | B1: Field label | C1: Value
A2: Facility details | B2: Facility identifier | C2: =IF(facilityID="","",facilityID)
A3: Facility details | B3: Facility name | C3: =IF(facilityName="","",facilityName)
A4: Facility details | B4: Facility address | C4: =IF(facilityAddress="","",facilityAddress)
A5: Facility details | B5: UK ETS | C5: =IF(facilityInETS="","",facilityInETS)
A6: Facility details | B6: BY start date | C6: =IF(facilityBYStartDate="","",facilityBYStartDate)
A7: Facility details | B7: Target type | C7: =IF(targetType="","",targetType)
A8: Facility details | B8: Energy units | C8: =IF(reportingUnits="","",reportingUnits)
A9: Base year fuel types | B9: TOTAL PRIMARY amount | C9: =primaryAmountAll -> 0
A10: Base year fuel types | B10: Weighted base year carbon emission factor | C10: =facilityBYWeightedCarbonFactor
A11: Base year fuel types | B11: PRIMARY amount grid electricity | C11: =primaryGridElec -> 0
A12: Base year fuel types | B12: PRIMARY amount non-grid electricity renewables | C12: =primaryNonGridElecRenewables -> 0
A13: Base year fuel types | B13: PRIMARY amount Natural gas | C13: =primaryNaturalGas -> 0
A14: Base year fuel types | B14: PRIMARY amount Fuel oil | C14: =primaryFuelOil -> 0
A15: Base year fuel types | B15: PRIMARY amount Coal | C15: =primaryCoal -> 0
A16: Base year fuel types | B16: PRIMARY amount Coke | C16: =primaryCoke -> 0
A17: Base year fuel types | B17: PRIMARY amount LPG | C17: =primaryLPG -> 0
A18: Base year fuel types | B18: PRIMARY amount Ethane | C18: =primaryEthane -> 0
A19: Base year fuel types | B19: PRIMARY amount Kerosene | C19: =primaryKerosene -> 0
A20: Base year fuel types | B20: PRIMARY amount Petrol | C20: =primaryPetrol -> 0
A21: Base year fuel types | B21: PRIMARY amount Gas oil/Diesel | C21: =primaryGasOil -> 0
A22: Base year fuel types | B22: PRIMARY amount Naphtha | C22: =primaryNaphtha -> 0
A23: Base year fuel types | B23: PRIMARY amount Petroleum Coke | C23: =primaryPetCoke -> 0
A24: Base year fuel types | B24: PRIMARY amount Refinery gas | C24: =primaryRefineryGas -> 0
A25: Base year fuel types | B25: Name Other Fuel 01 | C25: =nameOtherFuel01 -> Other Fuel 01
A26: Base year fuel types | B26: Conversion factor Other fuel 01 | C26: =IF(carbonFactorOtherFuel01="","",carbonFactorOtherFuel01)
A27: Base year fuel types | B27: PRIMARY amount Other Fuel 01 | C27: =primaryOtherFuel01 -> 0
A28: Base year fuel types | B28: Name Other Fuel 02 | C28: =nameOtherFuel02 -> Other Fuel 02
A29: Base year fuel types | B29: Conversion factor Other fuel 02 | C29: =IF(carbonFactorOtherFuel02="","",carbonFactorOtherFuel02)
A30: Base year fuel types | B30: PRIMARY amount Other Fuel 02 | C30: =primaryOtherFuel02 -> 0
A31: Base year fuel types | B31: Name Other Fuel 03 | C31: =nameOtherFuel03 -> Other Fuel 03
A32: Base year fuel types | B32: Conversion factor Other fuel 03 | C32: =IF(carbonFactorOtherFuel03="","",carbonFactorOtherFuel03)
A33: Base year fuel types | B33: PRIMARY amount Other Fuel 03 | C33: =primaryOtherFuel03 -> 0
A34: Base year fuel types | B34: Name Other Fuel 04 | C34: =nameOtherFuel04 -> Other Fuel 04
A35: Base year fuel types | B35: Conversion factor Other fuel 04 | C35: =IF(carbonFactorOtherFuel04="","",carbonFactorOtherFuel04)
A36: Base year fuel types | B36: PRIMARY amount Other Fuel 04 | C36: =primaryOtherFuel04 -> 0
A37: Base year fuel types | B37: Name Other Fuel 05 | C37: =nameOtherFuel05 -> Other Fuel 05
A38: Base year fuel types | B38: Conversion factor Other fuel 05 | C38: =IF(carbonFactorOtherFuel05="","",carbonFactorOtherFuel05)
A39: Base year fuel types | B39: PRIMARY amount Other Fuel 05 | C39: =primaryOtherFuel05 -> 0
A40: Base year fuel types | B40: Name Other Fuel 06 | C40: =nameOtherFuel06 -> Other Fuel 06
...

Sheet Monthly BY data (optional)
A1: ="Complete the table with monthly "&targetType&" and throughput data for a single product made during the base year period to estimate the FIXED and VARIABLE components" -> Complete the table with monthly and throughput data for a single product made during the base year period to estimate the FIXED and VARIABLE components
A3: Month | B3: Throughput units / month | C3: ="Actual "&targetType&" "&reportingUnits&" / month" -> Actual / month | D3: ="Calculated "&targetType&" "&reportingUnits&" / month" -> Calculated / month | E3: Difference
A4: =IF(facilityBYStartDate="","",EDATE(facilityBYStartDate,ROW(A4)-4)) | D4: =IFERROR($H$4/$H$7+$H$5*B4,"") | E4: =IFERROR(D4-C4,"") | G4: ="Fixed "&targetType -> Fixed | H4: =IF($H$7<12,"Enter more data",INTERCEPT('Monthly BY data (optional)'!$C$4:$C$15,'Monthly BY data (optional)'!$B$4:$B$15)*H7) -> Enter more data | I4: =reportingUnits&" / year" -> / year
A5: =IF(facilityBYStartDate="","",EDATE(facilityBYStartDate,ROW(A5)-4)) | D5: =IFERROR($H$4/$H$7+$H$5*B5,"") | E5: =IFERROR(D5-C5,"") | G5: =targetType&" intensity" -> intensity | H5: =IF($H$7<12,"Enter more data",SLOPE('Monthly BY data (optional)'!$C$4:$C$15,'Monthly BY data (optional)'!$B$4:$B$15)) -> Enter more data | I5: =reportingUnits&" / throughput unit" -> / throughput unit
A6: =IF(facilityBYStartDate="","",EDATE(facilityBYStartDate,ROW(A6)-4)) | D6: =IFERROR($H$4/$H$7+$H$5*B6,"") | E6: =IFERROR(D6-C6,"") | G6: R² value (coefficient of determination) | H6: =IF($H$7<12,"Enter more data",RSQ('Monthly BY data (optional)'!$C$4:$C$15,'Monthly BY data (optional)'!$B$4:$B$15)) -> Enter more data
A7: =IF(facilityBYStartDate="","",EDATE(facilityBYStartDate,ROW(A7)-4)) | D7: =IFERROR($H$4/$H$7+$H$5*B7,"") | E7: =IFERROR(D7-C7,"") | G7: Number of data points | H7: =COUNTA('Monthly BY data (optional)'!$B$4:$C$15)/2 -> 0
A8: =IF(facilityBYStartDate="","",EDATE(facilityBYStartDate,ROW(A8)-4)) | D8: =IFERROR($H$4/$H$7+$H$5*B8,"") | E8: =IFERROR(D8-C8,"")
A9: =IF(facilityBYStartDate="","",EDATE(facilityBYStartDate,ROW(A9)-4)) | D9: =IFERROR($H$4/$H$7+$H$5*B9,"") | E9: =IFERROR(D9-C9,"")
A10: =IF(facilityBYStartDate="","",EDATE(facilityBYStartDate,ROW(A10)-4)) | D10: =IFERROR($H$4/$H$7+$H$5*B10,"") | E10: =IFERROR(D10-C10,"")
A11: =IF(facilityBYStartDate="","",EDATE(facilityBYStartDate,ROW(A11)-4)) | D11: =IFERROR($H$4/$H$7+$H$5*B11,"") | E11: =IFERROR(D11-C11,"")
A12: =IF(facilityBYStartDate="","",EDATE(facilityBYStartDate,ROW(A12)-4)) | D12: =IFERROR($H$4/$H$7+$H$5*B12,"") | E12: =IFERROR(D12-C12,"")
A13: =IF(facilityBYStartDate="","",EDATE(facilityBYStartDate,ROW(A13)-4)) | D13: =IFERROR($H$4/$H$7+$H$5*B13,"") | E13: =IFERROR(D13-C13,"")
A14: =IF(facilityBYStartDate="","",EDATE(facilityBYStartDate,ROW(A14)-4)) | D14: =IFERROR($H$4/$H$7+$H$5*B14,"") | E14: =IFERROR(D14-C14,"")
A15: =IF(facilityBYStartDate="","",EDATE(facilityBYStartDate,ROW(A15)-4)) | D15: =IFERROR($H$4/$H$7+$H$5*B15,"") | E15: =IFERROR(D15-C15,"")
A16: Total | B16: =SUBTOTAL(109,'Monthly BY data (optional)'!$B$4:$B$15) -> 0 | C16: =SUBTOTAL(109,'Monthly BY data (optional)'!$C$4:$C$15) -> 0 | D16: =SUBTOTAL(109,'Monthly BY data (optional)'!$D$4:$D$15) -> 0 | E16: =SUBTOTAL(109,'Monthly BY data (optional)'!$E$4:$E$15) -> 0
A18: =targetType&" vs. throughput (12 months)" -> vs. throughput (12 months) | G18: ="Actual and calculated "&targetType&" per month" -> Actual and calculated per month
G19: =targetType&" ("&reportingUnits&")" -> ()

Sheet Weekly BY data (optional)
A1: Complete the table with weekly energy and throughput data for a single product made during the base year period to estimate the FIXED and VARIABLE components
A3: Week commencing | B3: Throughput units/week | C3: ="Actual "&targetType&" "&reportingUnits&" / week" -> Actual / week | D3: ="Predicted "&targetType&" "&reportingUnits&" / week" -> Predicted / week | E3: Difference
A4: =IF(facilityBYStartDate="","",facilityBYStartDate) | D4: =IFERROR($H$4/$H$7+$H$5*B4,"") | E4: =IFERROR(D4-C4,"") | G4: ="Fixed "&targetType -> Fixed | H4: =IF($H$7<52,"Enter more data",INTERCEPT('Weekly BY data (optional)'!$C$4:$C$55,'Weekly BY data (optional)'!$B$4:$B$55)*H7) -> Enter more data | I4: =reportingUnits&" / year" -> / year
A5: =IF(facilityBYStartDate="","",A4+7) | D5: =IFERROR($H$4/$H$7+$H$5*B5,"") | E5: =IFERROR(D5-C5,"") | G5: =targetType&" intensity" -> intensity | H5: =IF($H$7<52,"Enter more data",SLOPE('Weekly BY data (optional)'!$C$4:$C$55,'Weekly BY data (optional)'!$B$4:$B$55)) -> Enter more data | I5: =reportingUnits&" / throughput unit" -> / throughput unit
A6: =IF(facilityBYStartDate="","",A5+7) | D6: =IFERROR($H$4/$H$7+$H$5*B6,"") | E6: =IFERROR(D6-C6,"") | G6: R² value (coefficient of determination) | H6: =IF($H$7<52,"Enter more data",RSQ('Weekly BY data (optional)'!$C$4:$C$55,'Weekly BY data (optional)'!$B$4:$B$55)) -> Enter more data
A7: =IF(facilityBYStartDate="","",A6+7) | D7: =IFERROR($H$4/$H$7+$H$5*B7,"") | E7: =IFERROR(D7-C7,"") | G7: Observations | H7: =COUNTA('Weekly BY data (optional)'!$B$4:$C$55)/2 -> 0
A8: =IF(facilityBYStartDate="","",A7+7) | D8: =IFERROR($H$4/$H$7+$H$5*B8,"") | E8: =IFERROR(D8-C8,"")
A9: =IF(facilityBYStartDate="","",A8+7) | D9: =IFERROR($H$4/$H$7+$H$5*B9,"") | E9: =IFERROR(D9-C9,"")
A10: =IF(facilityBYStartDate="","",A9+7) | D10: =IFERROR($H$4/$H$7+$H$5*B10,"") | E10: =IFERROR(D10-C10,"") | G10: =targetType&" vs. throughput (52 weeks)" -> vs. throughput (52 weeks) | K10: ="Actual and calculated "&targetType&" per week" -> Actual and calculated per week
A11: =IF(facilityBYStartDate="","",A10+7) | D11: =IFERROR($H$4/$H$7+$H$5*B11,"") | E11: =IFERROR(D11-C11,"") | K11: =targetType&" ("&reportingUnits&")" -> ()
A12: =IF(facilityBYStartDate="","",A11+7) | D12: =IFERROR($H$4/$H$7+$H$5*B12,"") | E12: =IFERROR(D12-C12,"")
A13: =IF(facilityBYStartDate="","",A12+7) | D13: =IFERROR($H$4/$H$7+$H$5*B13,"") | E13: =IFERROR(D13-C13,"")
A14: =IF(facilityBYStartDate="","",A13+7) | D14: =IFERROR($H$4/$H$7+$H$5*B14,"") | E14: =IFERROR(D14-C14,"")
A15: =IF(facilityBYStartDate="","",A14+7) | D15: =IFERROR($H$4/$H$7+$H$5*B15,"") | E15: =IFERROR(D15-C15,"")
A16: =IF(facilityBYStartDate="","",A15+7) | D16: =IFERROR($H$4/$H$7+$H$5*B16,"") | E16: =IFERROR(D16-C16,"")
A17: =IF(facilityBYStartDate="","",A16+7) | D17: =IFERROR($H$4/$H$7+$H$5*B17,"") | E17: =IFERROR(D17-C17,"")
A18: =IF(facilityBYStartDate="","",A17+7) | D18: =IFERROR($H$4/$H$7+$H$5*B18,"") | E18: =IFERROR(D18-C18,"")
A19: =IF(facilityBYStartDate="","",A18+7) | D19: =IFERROR($H$4/$H$7+$H$5*B19,"") | E19: =IFERROR(D19-C19,"")
A20: =IF(facilityBYStartDate="","",A19+7) | D20: =IFERROR($H$4/$H$7+$H$5*B20,"") | E20: =IFERROR(D20-C20,"")
A21: =IF(facilityBYStartDate="","",A20+7) | D21: =IFERROR($H$4/$H$7+$H$5*B21,"") | E21: =IFERROR(D21-C21,"")
A22: =IF(facilityBYStartDate="","",A21+7) | D22: =IFERROR($H$4/$H$7+$H$5*B22,"") | E22: =IFERROR(D22-C22,"")
A23: =IF(facilityBYStartDate="","",A22+7) | D23: =IFERROR($H$4/$H$7+$H$5*B23,"") | E23: =IFERROR(D23-C23,"")
... A55: =IF(facilityBYStartDate="","",A54+7) | D55: =IFERROR($H$4/$H$7+$H$5*B55,"") | E55: =IFERROR(D55-C55,"")
A56: Total | B56: =SUBTOTAL(109,'Weekly BY data (optional)'!$B$4:$B$55) -> 0 | C56: =SUBTOTAL(109,'Weekly BY data (optional)'!$C$4:$C$55) -> 0 | D56: =SUBTOTAL(109,'Weekly BY data (optional)'!$D$4:$D$55) -> 0 | E56: =SUBTOTAL(109,'Weekly BY data (optional)'!$E$4:$E$55) -> 0
A58: ="Total primary base year "&targetType&" (excluding ETS) from the ""Base year fuel types"" tab" -> Total primary base year (excluding ETS) from the "Base year fuel types" tab
C59: =primaryBaseYearEnergy -> 0

Sheet Monthly BY multi-prod
A1: ="Complete the table with monthly "&targetType&" and throughput data for up to 15 products made during the base year period to estimate the FIXED and VARIABLE components" -> Complete the table with monthly and throughput data for up to 15 products made during the base year period to estimate the FIXED and VARIABLE components
A3: Month | B3: Product 1 | C3: Product 2 | D3: Product 3 | E3: Product 4 | F3: Product 5 | G3: Product 6 | H3: Product 7 | I3: Product 8 | J3: Product 9 | K3: Product 10 | L3: Product 11 | M3: Product 12 | N3: Product 13 | O3: Product 14 | P3: Product 15 | Q3: ="Actual "&targetType&" "&reportingUnits&" / month" -> Actual / month | R3: ="Calculated "&targetType&" "&reportingUnits&" / month" -> Calculated / month | S3: Difference
A4: =IF(facilityBYStartDate="","",EDATE(facilityBYStartDate,ROW(A4)-4)) | B4: 0 | C4: 0 | D4: 0 | E4: 0 | F4: 0 | G4: 0 | H4: 0 | I4: 0 | J4: 0 | K4: 0 | L4: 0 | M4: 0 | N4: 0 | O4: 0 | P4: 0 | Q4: 0 | R4: =$B$19/12+B4*$B$20+C4*$B$21+D4*$B$22+E4*$B$23+F4*$B$24+G4*$B$25+H4*$B$26+I4*$B$27+J4*$B$28+K4*$B$29+L4*$B$30+M4*$B$31+N4*$B$32+O4*$B$33+P4*$B$34 -> 0 | S4: =IFERROR(R4-Q4,"") -> 0
A5: =IF(facilityBYStartDate="","",EDATE(facilityBYStartDate,ROW(A5)-4)) | B5: 0 | C5: 0 | D5: 0 | E5: 0 | F5: 0 | G5: 0 | H5: 0 | I5: 0 | J5: 0 | K5: 0 | L5: 0 | M5: 0 | N5: 0 | O5: 0 | P5: 0 | Q5: 0 | R5: =$B$19/12+B5*$B$20+C5*$B$21+D5*$B$22+E5*$B$23+F5*$B$24+G5*$B$25+H5*$B$26+I5*$B$27+J5*$B$28+K5*$B$29+L5*$B$30+M5*$B$31+N5*$B$32+O5*$B$33+P5*$B$34 -> 0 | S5: =IFERROR(R5-Q5,"") -> 0
A6: =IF(facilityBYStartDate="","",EDATE(facilityBYStartDate,ROW(A6)-4)) | B6: 0 | C6: 0 | D6: 0 | E6: 0 | F6: 0 | G6: 0 | H6: 0 | I6: 0 | J6: 0 | K6: 0 | L6: 0 | M6: 0 | N6: 0 | O6: 0 | P6: 0 | Q6: 0 | R6: =$B$19/12+B6*$B$20+C6*$B$21+D6*$B$22+E6*$B$23+F6*$B$24+G6*$B$25+H6*$B$26+I6*$B$27+J6*$B$28+K6*$B$29+L6*$B$30+M6*$B$31+N6*$B$32+O6*$B$33+P6*$B$34 -> 0 | S6: =IFERROR(R6-Q6,"") -> 0
A7: =IF(facilityBYStartDate="","",EDATE(facilityBYStartDate,ROW(A7)-4)) | B7: 0 | C7: 0 | D7: 0 | E7: 0 | F7: 0 | G7: 0 | H7: 0 | I7: 0 | J7: 0 | K7: 0 | L7: 0 | M7: 0 | N7: 0 | O7: 0 | P7: 0 | Q7: 0 | R7: =$B$19/12+B7*$B$20+C7*$B$21+D7*$B$22+E7*$B$23+F7*$B$24+G7*$B$25+H7*$B$26+I7*$B$27+J7*$B$28+K7*$B$29+L7*$B$30+M7*$B$31+N7*$B$32+O7*$B$33+P7*$B$34 -> 0 | S7: =IFERROR(R7-Q7,"") -> 0
A8: =IF(facilityBYStartDate="","",EDATE(facilityBYStartDate,ROW(A8)-4)) | B8: 0 | C8: 0 | D8: 0 | E8: 0 | F8: 0 | G8: 0 | H8: 0 | I8: 0 | J8: 0 | K8: 0 | L8: 0 | M8: 0 | N8: 0 | O8: 0 | P8: 0 | Q8: 0 | R8: =$B$19/12+B8*$B$20+C8*$B$21+D8*$B$22+E8*$B$23+F8*$B$24+G8*$B$25+H8*$B$26+I8*$B$27+J8*$B$28+K8*$B$29+L8*$B$30+M8*$B$31+N8*$B$32+O8*$B$33+P8*$B$34 -> 0 | S8: =IFERROR(R8-Q8,"") -> 0
A9: =IF(facilityBYStartDate="","",EDATE(facilityBYStartDate,ROW(A9)-4)) | B9: 0 | C9: 0 | D9: 0 | E9: 0 | F9: 0 | G9: 0 | H9: 0 | I9: 0 | J9: 0 | K9: 0 | L9: 0 | M9: 0 | N9: 0 | O9: 0 | P9: 0 | Q9: 0 | R9: =$B$19/12+B9*$B$20+C9*$B$21+D9*$B$22+E9*$B$23+F9*$B$24+G9*$B$25+H9*$B$26+I9*$B$27+J9*$B$28+K9*$B$29+L9*$B$30+M9*$B$31+N9*$B$32+O9*$B$33+P9*$B$34 -> 0 | S9: =IFERROR(R9-Q9,"") -> 0
A10: =IF(facilityBYStartDate="","",EDATE(facilityBYStartDate,ROW(A10)-4)) | B10: 0 | C10: 0 | D10: 0 | E10: 0 | F10: 0 | G10: 0 | H10: 0 | I10: 0 | J10: 0 | K10: 0 | L10: 0 | M10: 0 | N10: 0 | O10: 0 | P10: 0 | Q10: 0 | R10: =$B$19/12+B10*$B$20+C10*$B$21+D10*$B$22+E10*$B$23+F10*$B$24+G10*$B$25+H10*$B$26+I10*$B$27+J10*$B$28+K10*$B$29+L10*$B$30+M10*$B$31+N10*$B$32+O10*$B$33+P10*$B$34 -> 0 | S10: =IFERROR(R10-Q10,"") -> 0
A11: =IF(facilityBYStartDate="","",EDATE(facilityBYStartDate,ROW(A11)-4)) | B11: 0 | C11: 0 | D11: 0 | E11: 0 | F11: 0 | G11: 0 | H11: 0 | I11: 0 | J11: 0 | K11: 0 | L11: 0 | M11: 0 | N11: 0 | O11: 0 | P11: 0 | Q11: 0 | R11: =$B$19/12+B11*$B$20+C11*$B$21+D11*$B$22+E11*$B$23+F11*$B$24+G11*$B$25+H11*$B$26+I11*$B$27+J11*$B$28+K11*$B$29+L11*$B$30+M11*$B$31+N11*$B$32+O11*$B$33+P11*$B$34 -> 0 | S11: =IFERROR(R11-Q11,"") -> 0
A12: =IF(facilityBYStartDate="","",EDATE(facilityBYStartDate,ROW(A12)-4)) | B12: 0 | C12: 0 | D12: 0 | E12: 0 | F12: 0 | G12: 0 | H12: 0 | I12: 0 | J12: 0 | K12: 0 | L12: 0 | M12: 0 | N12: 0 | O12: 0 | P12: 0 | Q12: 0 | R12: =$B$19/12+B12*$B$20+C12*$B$21+D12*$B$22+E12*$B$23+F12*$B$24+G12*$B$25+H12*$B$26+I12*$B$27+J12*$B$28+K12*$B$29+L12*$B$30+M12*$B$31+N12*$B$32+O12*$B$33+P12*$B$34 -> 0 | S12: =IFERROR(R12-Q12,"") -> 0
A13: =IF(facilityBYStartDate="","",EDATE(facilityBYStartDate,ROW(A13)-4)) | B13: 0 | C13: 0 | D13: 0 | E13: 0 | F13: 0 | G13: 0 | H13: 0 | I13: 0 | J13: 0 | K13: 0 | L13: 0 | M13: 0 | N13: 0 | O13: 0 | P13: 0 | Q13: 0 | R13: =$B$19/12+B13*$B$20+C13*$B$21+D13*$B$22+E13*$B$23+F13*$B$24+G13*$B$25+H13*$B$26+I13*$B$27+J13*$B$28+K13*$B$29+L13*$B$30+M13*$B$31+N13*$B$32+O13*$B$33+P13*$B$34 -> 0 | S13: =IFERROR(R13-Q13,"") -> 0
A14: =IF(facilityBYStartDate="","",EDATE(facilityBYStartDate,ROW(A14)-4)) | B14: 0 | C14: 0 | D14: 0 | E14: 0 | F14: 0 | G14: 0 | H14: 0 | I14: 0 | J14: 0 | K14: 0 | L14: 0 | M14: 0 | N14: 0 | O14: 0 | P14: 0 | Q14: 0 | R14: =$B$19/12+B14*$B$20+C14*$B$21+D14*$B$22+E14*$B$23+F14*$B$24+G14*$B$25+H14*$B$26+I14*$B$27+J14*$B$28+K14*$B$29+L14*$B$30+M14*$B$31+N14*$B$32+O14*$B$33+P14*$B$34 -> 0 | S14: =IFERROR(R14-Q14,"") -> 0
A15: =IF(facilityBYStartDate="","",EDATE(facilityBYStartDate,ROW(A15)-4)) | B15: 0 | C15: 0 | D15: 0 | E15: 0 | F15: 0 | G15: 0 | H15: 0 | I15: 0 | J15: 0 | K15: 0 | L15: 0 | M15: 0 | N15: 0 | O15: 0 | P15: 0 | Q15: 0 | R15: =$B$19/12+B15*$B$20+C15*$B$21+D15*$B$22+E15*$B$23+F15*$B$24+G15*$B$25+H15*$B$26+I15*$B$27+J15*$B$28+K15*$B$29+L15*$B$30+M15*$B$31+N15*$B$32+O15*$B$33+P15*$B$34 -> 0 | S15: =IFERROR(R15-Q15,"") -> 0
A16: Total | B16: =SUBTOTAL(109,B$4:B$15) -> 0 | C16: =SUBTOTAL(109,C$4:C$15) -> 0 | D16: =SUBTOTAL(109,D$4:D$15) -> 0 | E16: =SUBTOTAL(109,E$4:E$15) -> 0 | F16: =SUBTOTAL(109,F$4:F$15) -> 0 | G16: =SUBTOTAL(109,G$4:G$15) -> 0 | H16: =SUBTOTAL(109,H$4:H$15) -> 0 | I16: =SUBTOTAL(109,I$4:I$15) -> 0 | ... S16: =SUBTOTAL(109,S$4:S$15) -> 0
A18: Note: for the formulae below to work, you must enter 0 values for any products that aren't relevant. (Don't delete these or leave blank!) | O18: ="Total primary base year "&targetType&" (excluding ETS) from the ""Base year fuel types"" tab" -> Total primary base year (excluding ETS) from the "Base year fuel types" tab
A19: ="Fixed "&targetType -> Fixed | B19: {=INDEX(LINEST($Q$4:$Q$15,$B$4:$P$15),16)*12} -> 0 | C19: =reportingUnits&" / year" -> / year | Q19: =primaryBaseYearEnergy -> 0
A20: =targetType&" intensity ("&B3&")" -> intensity (Product 1) | B20: {=INDEX(LINEST($Q$4:$Q$15,$B$4:$P$15),15)} -> 0 | C20: =reportingUnits&" / throughput unit" -> / throughput unit
A21: =targetType&" intensity ("&C3&")" -> intensity (Product 2) | B21: {=INDEX(LINEST($Q$4:$Q$15,$B$4:$P$15),14)} -> 0 | C21: =reportingUnits&" / throughput unit" -> / throughput unit
A22: =targetType&" intensity ("&D3&")" -> intensity (Product 3) | B22: {=INDEX(LINEST($Q$4:$Q$15,$B$4:$P$15),13)} -> 0 | C22: =reportingUnits&" / throughput unit" -> / throughput unit
A23: =targetType&" intensity ("&E3&")" -> intensity (Product 4) | B23: {=INDEX(LINEST($Q$4:$Q$15,$B$4:$P$15),12)} -> 0 | C23: =reportingUnits&" / throughput unit" -> / throughput unit
A24: =targetType&" intensity ("&F3&")" -> intensity (Product 5) | B24: {=INDEX(LINEST($Q$4:$Q$15,$B$4:$P$15),11)} -> 0 | C24: =reportingUnits&" / throughput unit" -> / throughput unit
A25: =targetType&" intensity ("&G3&")" -> intensity (Product 6) | B25: {=INDEX(LINEST($Q$4:$Q$15,$B$4:$P$15),10)} -> 0 | C25: =reportingUnits&" / throughput unit" -> / throughput unit
A26: =targetType&" intensity ("&H3&")" -> intensity (Product 7) | B26: {=INDEX(LINEST($Q$4:$Q$15,$B$4:$P$15),9)} -> 0 | C26: =reportingUnits&" / throughput unit" -> / throughput unit
A27: =targetType&" intensity ("&I3&")" -> intensity (Product 8) | B27: {=INDEX(LINEST($Q$4:$Q$15,$B$4:$P$15),8)} -> 0 | C27: =reportingUnits&" / throughput unit" -> / throughput unit
A28: =targetType&" intensity ("&J3&")" -> intensity (Product 9) | B28: {=INDEX(LINEST($Q$4:$Q$15,$B$4:$P$15),7)} -> 0 | C28: =reportingUnits&" / throughput unit" -> / throughput unit
A29: =targetType&" intensity ("&K3&")" -> intensity (Product 10) | B29: {=INDEX(LINEST($Q$4:$Q$15,$B$4:$P$15),6)} -> 0 | C29: =reportingUnits&" / throughput unit" -> / throughput unit
A30: =targetType&" intensity ("&L3&")" -> intensity (Product 11) | B30: {=INDEX(LINEST($Q$4:$Q$15,$B$4:$P$15),5)} -> 0 | C30: =reportingUnits&" / throughput unit" -> / throughput unit
A31: =targetType&" intensity ("&M3&")" -> intensity (Product 12) | B31: {=INDEX(LINEST($Q$4:$Q$15,$B$4:$P$15),4)} -> 0 | C31: =reportingUnits&" / throughput unit" -> / throughput unit
A32: =targetType&" intensity ("&N3&")" -> intensity (Product 13) | B32: {=INDEX(LINEST($Q$4:$Q$15,$B$4:$P$15),3)} -> 0 | C32: =reportingUnits&" / throughput unit" -> / throughput unit
A33: =targetType&" intensity ("&O3&")" -> intensity (Product 14) | B33: {=INDEX(LINEST($Q$4:$Q$15,$B$4:$P$15),2)} -> 0 | C33: =reportingUnits&" / throughput unit" -> / throughput unit
A34: =targetType&" intensity ("&P3&")" -> intensity (Product 15) | B34: {=INDEX(LINEST($Q$4:$Q$15,$B$4:$P$15),1)} -> 0 | C34: =reportingUnits&" / throughput unit" -> / throughput unit

Sheet Weekly BY multi-prod
A1: Complete the table with weekly energy and throughput data for a single product made during the base year period to estimate the FIXED and VARIABLE components
A3: Week commencing | B3: Product 1 | C3: Product 2 | D3: Product 3 | E3: Product 4 | F3: Product 5 | G3: Product 6 | H3: Product 7 | I3: Product 8 | J3: Product 9 | K3: Product 10 | L3: Product 11 | M3: Product 12 | N3: Product 13 | O3: Product 14 | P3: Product 15 | Q3: ="Actual "&targetType&" "&reportingUnits&" / week" -> Actual / week | R3: ="Predicted "&targetType&" "&reportingUnits&" / week" -> Predicted / week | S3: Difference
A4: =IF(facilityBYStartDate="","",facilityBYStartDate) | B4: 0 | C4: 0 | D4: 0 | E4: 0 | F4: 0 | G4: 0 | H4: 0 | I4: 0 | J4: 0 | K4: 0 | L4: 0 | M4: 0 | N4: 0 | O4: 0 | P4: 0 | Q4: 0 | R4: =fixWkly/52+B4*varWklyProd1+C4*varWklyProd2+D4*varWklyProd3+E4*varWklyProd4+F4*varWklyProd5+G4*varWklyProd6+H4*varWklyProd7+I4*varWklyProd8+J4*varWklyProd9+K4*varWklyProd10+L4*varWklyProd11+M4*varWklyProd12+N4*varWklyProd13+O4*varWklyProd14+P4*varWklyProd15 -> 0 | S4: =IFERROR(R4-Q4,"") -> 0
A5: =IF(facilityBYStartDate="","",A4+7) | B5: 0 | C5: 0 | D5: 0 | E5: 0 | F5: 0 | G5: 0 | H5: 0 | I5: 0 | J5: 0 | K5: 0 | L5: 0 | M5: 0 | N5: 0 | O5: 0 | P5: 0 | Q5: 0 | R5: =fixWkly/52+B5*varWklyProd1+C5*varWklyProd2+D5*varWklyProd3+E5*varWklyProd4+F5*varWklyProd5+G5*varWklyProd6+H5*varWklyProd7+I5*varWklyProd8+J5*varWklyProd9+K5*varWklyProd10+L5*varWklyProd11+M5*varWklyProd12+N5*varWklyProd13+O5*varWklyProd14+P5*varWklyProd15 -> 0 | S5: =IFERROR(R5-Q5,"") -> 0
A6: =IF(facilityBYStartDate="","",A5+7) | B6: 0 | C6: 0 | D6: 0 | E6: 0 | F6: 0 | G6: 0 | H6: 0 | I6: 0 | J6: 0 | K6: 0 | L6: 0 | M6: 0 | N6: 0 | O6: 0 | P6: 0 | Q6: 0 | R6: =fixWkly/52+B6*varWklyProd1+C6*varWklyProd2+D6*varWklyProd3+E6*varWklyProd4+F6*varWklyProd5+G6*varWklyProd6+H6*varWklyProd7+I6*varWklyProd8+J6*varWklyProd9+K6*varWklyProd10+L6*varWklyProd11+M6*varWklyProd12+N6*varWklyProd13+O6*varWklyProd14+P6*varWklyProd15 -> 0 | S6: =IFERROR(R6-Q6,"") -> 0
A7: =IF(facilityBYStartDate="","",A6+7) | B7: 0 | C7: 0 | D7: 0 | E7: 0 | F7: 0 | G7: 0 | H7: 0 | I7: 0 | J7: 0 | K7: 0 | L7: 0 | M7: 0 | N7: 0 | O7: 0 | P7: 0 | Q7: 0 | R7: =fixWkly/52+B7*varWklyProd1+C7*varWklyProd2+D7*varWklyProd3+E7*varWklyProd4+F7*varWklyProd5+G7*varWklyProd6+H7*varWklyProd7+I7*varWklyProd8+J7*varWklyProd9+K7*varWklyProd10+L7*varWklyProd11+M7*varWklyProd12+N7*varWklyProd13+O7*varWklyProd14+P7*varWklyProd15 -> 0 | S7: =IFERROR(R7-Q7,"") -> 0
A8: =IF(facilityBYStartDate="","",A7+7) | B8: 0 | C8: 0 | D8: 0 | E8: 0 | F8: 0 | G8: 0 | H8: 0 | I8: 0 | J8: 0 | K8: 0 | L8: 0 | M8: 0 | N8: 0 | O8: 0 | P8: 0 | Q8: 0 | R8: =fixWkly/52+B8*varWklyProd1+C8*varWklyProd2+D8*varWklyProd3+E8*varWklyProd4+F8*varWklyProd5+G8*varWklyProd6+H8*varWklyProd7+I8*varWklyProd8+J8*varWklyProd9+K8*varWklyProd10+L8*varWklyProd11+M8*varWklyProd12+N8*varWklyProd13+O8*varWklyProd14+P8*varWklyProd15 -> 0 | S8: =IFERROR(R8-Q8,"") -> 0
A9: =IF(facilityBYStartDate="","",A8+7) | B9: 0 | C9: 0 | D9: 0 | E9: 0 | F9: 0 | G9: 0 | H9: 0 | I9: 0 | J9: 0 | K9: 0 | L9: 0 | M9: 0 | N9: 0 | O9: 0 | P9: 0 | Q9: 0 | R9: =fixWkly/52+B9*varWklyProd1+C9*varWklyProd2+D9*varWklyProd3+E9*varWklyProd4+F9*varWklyProd5+G9*varWklyProd6+H9*varWklyProd7+I9*varWklyProd8+J9*varWklyProd9+K9*varWklyProd10+L9*varWklyProd11+M9*varWklyProd12+N9*varWklyProd13+O9*varWklyProd14+P9*varWklyProd15 -> 0 | S9: =IFERROR(R9-Q9,"") -> 0
A10: =IF(facilityBYStartDate="","",A9+7) | B10: 0 | C10: 0 | D10: 0 | E10: 0 | F10: 0 | G10: 0 | H10: 0 | I10: 0 | J10: 0 | K10: 0 | L10: 0 | M10: 0 | N10: 0 | O10: 0 | P10: 0 | Q10: 0 | R10: =fixWkly/52+B10*varWklyProd1+C10*varWklyProd2+D10*varWklyProd3+E10*varWklyProd4+F10*varWklyProd5+G10*varWklyProd6+H10*varWklyProd7+I10*varWklyProd8+J10*varWklyProd9+K10*varWklyProd10+L10*varWklyProd11+M10*varWklyProd12+N10*varWklyProd13+O10*varWklyProd14+P10*varWklyProd15 -> 0 | S10: =IFERROR(R10-Q10,"") -> 0
A11: =IF(facilityBYStartDate="","",A10+7) | B11: 0 | C11: 0 | D11: 0 | E11: 0 | F11: 0 | G11: 0 | H11: 0 | I11: 0 | J11: 0 | K11: 0 | L11: 0 | M11: 0 | N11: 0 | O11: 0 | P11: 0 | Q11: 0 | R11: =fixWkly/52+B11*varWklyProd1+C11*varWklyProd2+D11*varWklyProd3+E11*varWklyProd4+F11*varWklyProd5+G11*varWklyProd6+H11*varWklyProd7+I11*varWklyProd8+J11*varWklyProd9+K11*varWklyProd10+L11*varWklyProd11+M11*varWklyProd12+N11*varWklyProd13+O11*varWklyProd14+P11*varWklyProd15 -> 0 | S11: =IFERROR(R11-Q11,"") -> 0
A12: =IF(facilityBYStartDate="","",A11+7) | B12: 0 | C12: 0 | D12: 0 | E12: 0 | F12: 0 | G12: 0 | H12: 0 | I12: 0 | J12: 0 | K12: 0 | L12: 0 | M12: 0 | N12: 0 | O12: 0 | P12: 0 | Q12: 0 | R12: =fixWkly/52+B12*varWklyProd1+C12*varWklyProd2+D12*varWklyProd3+E12*varWklyProd4+F12*varWklyProd5+G12*varWklyProd6+H12*varWklyProd7+I12*varWklyProd8+J12*varWklyProd9+K12*varWklyProd10+L12*varWklyProd11+M12*varWklyProd12+N12*varWklyProd13+O12*varWklyProd14+P12*varWklyProd15 -> 0 | S12: =IFERROR(R12-Q12,"") -> 0
A13: =IF(facilityBYStartDate="","",A12+7) | B13: 0 | C13: 0 | D13: 0 | E13: 0 | F13: 0 | G13: 0 | H13: 0 | I13: 0 | J13: 0 | K13: 0 | L13: 0 | M13: 0 | N13: 0 | O13: 0 | P13: 0 | Q13: 0 | R13: =fixWkly/52+B13*varWklyProd1+C13*varWklyProd2+D13*varWklyProd3+E13*varWklyProd4+F13*varWklyProd5+G13*varWklyProd6+H13*varWklyProd7+I13*varWklyProd8+J13*varWklyProd9+K13*varWklyProd10+L13*varWklyProd11+M13*varWklyProd12+N13*varWklyProd13+O13*varWklyProd14+P13*varWklyProd15 -> 0 | S13: =IFERROR(R13-Q13,"") -> 0
A14: =IF(facilityBYStartDate="","",A13+7) | B14: 0 | C14: 0 | D14: 0 | E14: 0 | F14: 0 | G14: 0 | H14: 0 | I14: 0 | J14: 0 | K14: 0 | L14: 0 | M14: 0 | N14: 0 | O14: 0 | P14: 0 | Q14: 0 | R14: =fixWkly/52+B14*varWklyProd1+C14*varWklyProd2+D14*varWklyProd3+E14*varWklyProd4+F14*varWklyProd5+G14*varWklyProd6+H14*varWklyProd7+I14*varWklyProd8+J14*varWklyProd9+K14*varWklyProd10+L14*varWklyProd11+M14*varWklyProd12+N14*varWklyProd13+O14*varWklyProd14+P14*varWklyProd15 -> 0 | S14: =IFERROR(R14-Q14,"") -> 0
A15: =IF(facilityBYStartDate="","",A14+7) | B15: 0 | C15: 0 | D15: 0 | E15: 0 | F15: 0 | G15: 0 | H15: 0 | I15: 0 | J15: 0 | K15: 0 | L15: 0 | M15: 0 | N15: 0 | O15: 0 | P15: 0 | Q15: 0 | R15: =fixWkly/52+B15*varWklyProd1+C15*varWklyProd2+D15*varWklyProd3+E15*varWklyProd4+F15*varWklyProd5+G15*varWklyProd6+H15*varWklyProd7+I15*varWklyProd8+J15*varWklyProd9+K15*varWklyProd10+L15*varWklyProd11+M15*varWklyProd12+N15*varWklyProd13+O15*varWklyProd14+P15*varWklyProd15 -> 0 | S15: =IFERROR(R15-Q15,"") -> 0
A16: =IF(facilityBYStartDate="","",A15+7) | B16: 0 | C16: 0 | D16: 0 | E16: 0 | F16: 0 | G16: 0 | H16: 0 | I16: 0 | J16: 0 | K16: 0 | L16: 0 | M16: 0 | N16: 0 | O16: 0 | P16: 0 | Q16: 0 | R16: =fixWkly/52+B16*varWklyProd1+C16*varWklyProd2+D16*varWklyProd3+E16*varWklyProd4+F16*varWklyProd5+G16*varWklyProd6+H16*varWklyProd7+I16*varWklyProd8+J16*varWklyProd9+K16*varWklyProd10+L16*varWklyProd11+M16*varWklyProd12+N16*varWklyProd13+O16*varWklyProd14+P16*varWklyProd15 -> 0 | S16: =IFERROR(R16-Q16,"") -> 0
... A55: =IF(facilityBYStartDate="","",A54+7) | B55: 0 | C55: 0 | D55: 0 | E55: 0 | F55: 0 | G55: 0 | H55: 0 | I55: 0 | J55: 0 | K55: 0 | L55: 0 | M55: 0 | N55: 0 | O55: 0 | P55: 0 | Q55: 0 | R55: =fixWkly/52+B55*varWklyProd1+C55*varWklyProd2+D55*varWklyProd3+E55*varWklyProd4+F55*varWklyProd5+G55*varWklyProd6+H55*varWklyProd7+I55*varWklyProd8+J55*varWklyProd9+K55*varWklyProd10+L55*varWklyProd11+M55*varWklyProd12+N55*varWklyProd13+O55*varWklyProd14+P55*varWklyProd15 -> 0 | S55: =IFERROR(R55-Q55,"") -> 0
A56: Total | B56: =SUBTOTAL(109,B$4:B$55) -> 0 | C56: =SUBTOTAL(109,C$4:C$55) -> 0 | D56: =SUBTOTAL(109,D$4:D$55) -> 0 | E56: =SUBTOTAL(109,E$4:E$55) -> 0 | F56: =SUBTOTAL(109,F$4:F$55) -> 0 | G56: =SUBTOTAL(109,G$4:G$55) -> 0 | H56: =SUBTOTAL(109,H$4:H$55) -> 0 | I56: =SUBTOTAL(109,I$4:I$55) -> 0 | ... S56: =SUBTOTAL(109,S$4:S$55) -> 0
A58: Note: for the formulae below to work, you must enter 0 values for any products that aren't relevant. (Don't delete these or leave blank!) | O58: ="Total primary base year "&targetType&" (excluding ETS) from the ""Base year fuel types"" tab" -> Total primary base year (excluding ETS) from the "Base year fuel types" tab
A59: ="Fixed "&targetType -> Fixed | B59: {=INDEX(LINEST($Q$4:$Q$55,$B$4:$P$55),16)*52} -> 0 | C59: =reportingUnits&" / year" -> / year | Q59: =primaryBaseYearEnergy -> 0
A60: =targetType&" intensity ("&B3&")" -> intensity (Product 1) | B60: {=INDEX(LINEST($Q$4:$Q$55,$B$4:$P$55),15)} -> 0 | C60: =reportingUnits&" / throughput unit" -> / throughput unit
A61: =targetType&" intensity ("&C3&")" -> intensity (Product 2) | B61: {=INDEX(LINEST($Q$4:$Q$55,$B$4:$P$55),14)} -> 0 | C61: =reportingUnits&" / throughput unit" -> / throughput unit
A62: =targetType&" intensity ("&D3&")" -> intensity (Product 3) | B62: {=INDEX(LINEST($Q$4:$Q$55,$B$4:$P$55),13)} -> 0 | C62: =reportingUnits&" / throughput unit" -> / throughput unit
A63: =targetType&" intensity ("&E3&")" -> intensity (Product 4) | B63: {=INDEX(LINEST($Q$4:$Q$55,$B$4:$P$55),12)} -> 0 | C63: =reportingUnits&" / throughput unit" -> / throughput unit
A64: =targetType&" intensity ("&F3&")" -> intensity (Product 5) | B64: {=INDEX(LINEST($Q$4:$Q$55,$B$4:$P$55),11)} -> 0 | C64: =reportingUnits&" / throughput unit" -> / throughput unit
A65: =targetType&" intensity ("&G3&")" -> intensity (Product 6) | B65: {=INDEX(LINEST($Q$4:$Q$55,$B$4:$P$55),10)} -> 0 | C65: =reportingUnits&" / throughput unit" -> / throughput unit
A66: =targetType&" intensity ("&H3&")" -> intensity (Product 7) | B66: {=INDEX(LINEST($Q$4:$Q$55,$B$4:$P$55),9)} -> 0 | C66: =reportingUnits&" / throughput unit" -> / throughput unit
A67: =targetType&" intensity ("&I3&")" -> intensity (Product 8) | B67: {=INDEX(LINEST($Q$4:$Q$55,$B$4:$P$55),8)} -> 0 | C67: =reportingUnits&" / throughput unit" -> / throughput unit
A68: =targetType&" intensity ("&J3&")" -> intensity (Product 9) | B68: {=INDEX(LINEST($Q$4:$Q$55,$B$4:$P$55),7)} -> 0 | C68: =reportingUnits&" / throughput unit" -> / throughput unit
A69: =targetType&" intensity ("&K3&")" -> intensity (Product 10) | B69: {=INDEX(LINEST($Q$4:$Q$55,$B$4:$P$55),6)} -> 0 | C69: =reportingUnits&" / throughput unit" -> / throughput unit
A70: =targetType&" intensity ("&L3&")" -> intensity (Product 11) | B70: {=INDEX(LINEST($Q$4:$Q$55,$B$4:$P$55),5)} -> 0 | C70: =reportingUnits&" / throughput unit" -> / throughput unit
A71: =targetType&" intensity ("&M3&")" -> intensity (Product 12) | B71: {=INDEX(LINEST($Q$4:$Q$55,$B$4:$P$55),4)} -> 0 | C71: =reportingUnits&" / throughput unit" -> / throughput unit
A72: =targetType&" intensity ("&N3&")" -> intensity (Product 13) | B72: {=INDEX(LINEST($Q$4:$Q$55,$B$4:$P$55),3)} -> 0 | C72: =reportingUnits&" / throughput unit" -> / throughput unit
A73: =targetType&" intensity ("&O3&")" -> intensity (Product 14) | B73: {=INDEX(LINEST($Q$4:$Q$55,$B$4:$P$55),2)} -> 0 | C73: =reportingUnits&" / throughput unit" -> / throughput unit
A74: =targetType&" intensity ("&P3&")" -> intensity (Product 15) | B74: {=INDEX(LINEST($Q$4:$Q$55,$B$4:$P$55),1)} -> 0 | C74: =reportingUnits&" / throughput unit" -> / throughput unit

Sheet Fuels
A1: UK Government GHG Conversion Factors for Company Reporting
A2: Fuels
A3: Index
B5: Emissions source: | C5: Fuels | D5: Next publication date: | E5: 45085 | F5: Factor set: | G5: Full set
B6: Scope: | C6: Scope 1 | D6: Version: | E6: 2 | F6: Year: | G6: 2022
B8: Fuels conversion factors should be used for primary fuel sources combusted at a site or in an asset owned or controlled by the reporting organisation.
B10: Guidance
B11: ● Gross calorific value (CV)/ net CV basis - Organisations should determine whether to use the net or gross calorific value of fuels according to their data. For example, the majority of energy billing is provided on a gross CV basis.
B12: ● 'Diesel (average biofuel blend)'/'diesel (100% mineral oil)' - typically organisations purchasing forecourt fuel should use 'diesel (average biofuel blend)'. It should be noted that any fuel an organisation reports in Scope 1 that has biofuel content must have the ‘outside of scopes’ portion reported separately as per the 'WBCSD/WRI GHG Protocol (chapter 9)'. See information about the outside of scopes emissions in the example section below. ● In 2019 update, a new factor for natural gas, "natural gas (100% mineral blend)", was added in. The difference between the "natural gas" and "natural gas (100% mineral blend)" factors is that the former refers to the natural gas received through the gas mains grid network in the UK containing a limited biogas content. Therefore, any organisation that reports emissions from natural gas use should use the "natural gas" factor. The natural gas (100% mineral blend) factor can be used for calculating bespoke fuel mixtures.
B13: ● If any fuel type or unit has no result in the table, this is an indication the conversion factor is not available or does not exist (such as lubricants in litres).
B14: Example of calculating emissions from fuels
B15: Company A needs to report the Scope 1 emissions from its natural gas and diesel use.
B16: ● For natural gas consumption it selects a kWh conversion factor on a gross CV basis - this is the basis of most energy bills. It reports in CO2e for all fuels combusted at its premises.
B17: ● It is faced with two different types of diesel conversion factors, '100% mineral fuel' and 'diesel (average biofuel blend)'. Since it fills up its vehicles at a national chain of filling stations, it selects the average biofuel blend (this is the correct conversion factor for standard forecourt fuel, which contains a small blend of biofuel).
B18: The activity data (that is, litres) is multiplied by the appropriate conversion factor to produce company A's fuel emissions. Organisations should determine whether to use the net or gross calorific value of fuels according to their data. For example, the majority of energy billing is provided on a gross CV basis.
B19: Since company A is reporting a type of fuel that has biofuel content, it should also account for the ‘biogenic’ part of this fuel. To calculate this, it must also multiply the total litres of fuel used by the ‘outside of scopes’ fuel factor for ‘forecourt fuels- diesel (average biofuel blend)’ and report as a separate line item within its report called ‘outside of scopes’. This will not be included in the organisation's emissions total, but displayed separately within the emissions report. This ensures that the organisation is being transparent with regard to all potential sources of CO2 from its activities.
B20: For more information refer to the ‘Outside of scopes’ tab for guidance.
B22: Activity | C22: Fuel | D22: Unit | E22: Total kg CO2e per unit | F22: kg CO2e of CO2 per unit | G22: kg CO2e of CH4 per unit | H22: kg CO2e of N2O per unit
B23: Gaseous fuels | C23: Butane | D23: tonnes | E23: 3033.32 | F23: 3029.26 | G23: 2.25 | H23: 1.8
D24: litres | E24: 1.74529 | F24: 1.74296 | G24: 0.00129 | H24: 0.00104
D25: kWh (Net CV) | E25: 0.24106 | F25: 0.24074 | G25: 0.00018 | H25: 0.00014
D26: kWh (Gross CV) | E26: 0.2224 | F26: 0.2221 | G26: 0.00017 | H26: 0.00013
C27: CNG | D27: tonnes | E27: 2539.25 | F27: 2534.47 | G27: 3.44 | H27: 1.34
D28: litres | E28: 0.44436 | F28: 0.44353 | G28: 0.0006 | H28: 0.00023
D29: kWh (Net CV) | E29: 0.20227 | F29: 0.20188 | G29: 0.00028 | H29: 0.00011
D30: kWh (Gross CV) | E30: 0.18254 | F30: 0.18219 | G30: 0.00025 | H30: 0.0001
C31: LNG | D31: tonnes | E31: 2559.17 | F31: 2554.39 | G31: 3.44 | H31: 1.34
D32: litres | E32: 1.158 | F32: 1.15583 | G32: 0.00156 | H32: 0.00061
D33: kWh (Net CV) | E33: 0.20386 | F33: 0.20347 | G33: 0.00028 | H33: 0.00011
D34: kWh (Gross CV) | E34: 0.18397 | F34: 0.18362 | G34: 0.00025 | H34: 0.0001
C35: LPG | D35: tonnes | E35: 2939.29 | F35: 2935.18 | G35: 2.28 | H35: 1.83
D36: litres | E36: 1.55709 | F36: 1.55491 | G36: 0.00121 | H36: 0.00097
D37: kWh (Net CV) | E37: 0.23031 | F37: 0.22999 | G37: 0.00018 | H37: 0.00014
D38: kWh (Gross CV) | E38: 0.21449 | F38: 0.21419 | G38: 0.00017 | H38: 0.00013
C39: Natural gas | D39: tonnes | E39: 2539.25 | F39: 2534.47 | G39: 3.44 | H39: 1.34
D40: cubic metres | E40: 2.01574 | F40: 2.01193 | G40: 0.00274 | H40: 0.00107
D41: kWh (Net CV) | E41: 0.20227 | F41: 0.20188 | G41: 0.00028 | H41: 0.00011
D42: kWh (Gross CV) | E42: 0.18254 | F42: 0.18219 | G42: 0.00025 | H42: 0.0001
C43: Natural gas (100% mineral blend) | D43: tonnes | E43: 2559.17 | F43: 2554.39 | G43: 3.44 | H43: 1.34
D44: cubic metres | E44: 2.03155 | F44: 2.02774 | G44: 0.00274 | H44: 0.00107
...

Sheet Fuel properties
A1: UK Government GHG Conversion Factors for Company Reporting
A2: Fuel properties
A3: Index
B5: Emissions source: | C5: None | D5: Next publication date: | E5: 45085 | F5: Factor set: | G5: Full set
B6: Scope: | C6: - | D6: Version: | E6: 2 | F6: Year: | G6: 2022
B8: The fuel properties can be used to determine the typical calorific values/densities of most common fuels.
D13: Year | E13: Net CV | F13: Gross CV | G13: Density | H13: Density* | J13: Net CV | K13: Gross CV | M13: Net CV | N13: Gross CV
E14: GJ/tonne | F14: GJ/tonne | G14: kg/m3 | H14: litres/tonne | J14: kWh/kg | K14: kWh/kg | M14: kWh/litre | N14: kWh/litre
B15: Commonly Used Fossil Fuels | C15: Aviation Spirit | D15: 2022 | E15: 44.831 | F15: 47.19 | G15: 727.273 | H15: 1375 | J15: 12.453 | K15: 13.108 | M15: 9.057 | N15: 9.533
